Workbook
Name Periodicity: 'Model Inputs'!$E$7

Sheet Notes

Sheet Cover
B2: Formatting Conventions
D4: Input | E4: 1000 | F4: Fundamental model inputs / assumptions, hardcoded value
D6: Technical Input | E6: 1000 | F6: Input values that determine model integrity / structure and should not be changed
D8: Calculation | E8: 1000 | F8: Stand-alone calculation or reference within sheet
D10: Linked | E10: 1000 | F10: Reference to a different sheet
D12: Sensitivity | E12: 1000 | F12: Input cell linked to sensivity analysis
D14: Blank | F14: Cell left intentionally blank for a functional purpose, may have dependents
D16: Explanatory | E16: ABC | F16: Contextual support
D18: Note | E18: ABC | F18: Additional information

Sheet Project Inputs
B2: LAND
C4: Details
D5: Model | E5: =Output!E9 -> Operating Lease | F5: "Ownership" covers both freehold and pre-paid ground lease
D6: Land Area | E6: 49109 | F6: sqm
C8: Value | E8: Per sqm | F8: Total
D9: Value (excl GST) | E9: 150 | F9: =Output!E12*$E$6 -> 9821800
D10: Value (incl GST) | E10: =Output!E12*1.15 -> 230 | F10: =E10*$E$6 -> 11295070
C12: Lease
D13: Cap Rate | E13: 0.06 | F13: applied to the GST inclusive land value
D14: Rental - annual (incl GST) | E14: =Output!E15*F10 -> 677704.2
D15: Rental - period (incl GST) | E15: =E14/Periodicity -> 56475.35
B18: DEVELOPMENT OVERVIEW
D20: Unit Type | E20: Description | F20: Typology | G20: Bedrooms | H20: Bathrooms | I20: Garages | J20: Floor Area | K20: Value Ratio | L20: Market Value | M20: Quantity | N20: Value Ratio Reworked | O20: Value per SQm | P20: Sales lag
D21: KDG | E21: Standalone | F21: House | G21: 3 | H21: 2 | I21: 2 | J21: 180 | K21: 1.25 | L21: =$E$41*N21 -> 1384943.2 | M21: 0 | N21: =K21/88%*100% -> 1.4204545
D22: HDG | E22: Standalone | F22: House | G22: 3 | H22: 2 | I22: 2 | J22: 180 | K22: 1.02 | L22: =$E$42*N22 -> 1275000 | M22: 0 | N22: =K22/88%*100% -> 1.1590909
D23: NDG | E23: Standalone | F23: House | G23: 3 | H23: 2 | I23: 2 | J23: 180 | K23: 1 | L23: =$E$42*N23 -> 1250000 | M23: 0 | N23: =K23/88%*100% -> 1.1363636
D24: BSG | E24: 2 bed duplex | F24: House | G24: 2 | H24: 1.5 | I24: 1 | J24: 121.6 | K24: 0.78 | L24: =$E$41*N24 -> 975000 | M24: 53 | N24: 1 | O24: =L24/J24 -> 8018.0921
D25: JMSG | E25: 2 bed duplex | F25: House | G25: 2 | H25: 1.5 | I25: 1 | J25: 120.9 | K25: 0.77 | L25: =$E$41*N25 -> 962500 | M25: 0 | N25: =K25/78%*100% -> 0.98717949
D26: JMDG | E26: 2 bed duplex | F26: House | G26: 2 | H26: 1.5 | I26: 2 | J26: 137.1 | K26: 0.8 | L26: =$E$41*N26 -> 1000000 | M26: 0 | N26: =K26/78%*100% -> 1.025641
D27: ESG | E27: 3 bed duplex | F27: House | G27: 3 | H27: 2 | I27: 1 | J27: 133.4 | K27: 0.885 | L27: =$E$42*N27 -> 1106250 | M27: 0 | N27: =K27/88%*100% -> 1.0056818
D28: MSG | E28: 3 bed duplex | F28: House | G28: 3 | H28: 2 | I28: 1 | J28: 139.33 | K28: 0.887 | L28: =$E$42*N28 -> 1108750 | M28: 0 | N28: =K28/88%*100% -> 1.0079545
D29: MNSG | E29: 3bd (mix dpl and stand) | F29: House | G29: 3 | H29: 2 | I29: 1 | J29: 144.2 | K29: 0.88 | L29: =$E$42*N29 -> 1100000 | M29: 32 | N29: 1 | O29: =L29/J29 -> 7628.294
D30: LSG | E30: 3 bed duplex | F30: House | G30: 3 | H30: 2 | I30: 1 | J30: 145.67 | K30: 0.88 | L30: =$E$42*N30 -> 1100000 | M30: 0 | N30: =K30/88%*100% -> 1
D31: MDG | E31: 3 bed duplex | F31: House | G31: 3 | H31: 2 | I31: 2 | J31: 155.58 | K31: 0.96 | L31: =$E$42*N31 -> 1200000 | M31: 0 | N31: =K31/88%*100% -> 1.0909091
D32: R6 | E32: 1 bed dplx | F32: House | G32: 1 | H32: 1 | I32: 1 | J32: 90 | K32: 0.65 | L32: =$E$41*N32 -> 812500 | M32: 20 | N32: =K32/78%*100% -> 0.83333333 | O32: =L32/J32 -> 9027.7778
D33: S1 | E33: Stanaway | F33: Apartment | G33: 2 | H33: 2 | I33: 1 | J33: 148.69605 | K33: 0.86 | L33: =$E$41*N33 -> 1075000 | M33: 0 | N33: =K33/78%*100% -> 1.1025641
D34: S2 | E34: Stanaway | F34: Apartment | G34: 2 | H34: 2 | I34: 1 | J34: 139.60596 | K34: 0.86 | L34: =$E$41*N34 -> 1075000 | M34: 0 | N34: =K34/78%*100% -> 1.1025641
D35: S3 | E35: Stanaway | F35: Apartment | G35: 2 | H35: 2 | I35: 1 | J35: 152.21767 | K35: 0.92 | L35: =$E$41*N35 -> 1150000 | M35: 0 | N35: =K35/78%*100% -> 1.1794872
D36: S4 | E36: Stanaway | F36: Apartment | G36: 3.5 | H36: 2 | I36: 1 | J36: 238.78328 | K36: 0.89 | L36: 0 | M36: 0 | N36: N/A
D37: S5 | E37: Stanaway | F37: Apartment | G37: 2.5 | H37: 2 | I37: 1 | J37: 198.64704 | K37: 0.92 | L37: 0 | M37: 0 | N37: N/A
D38: Total / Weighted Average | L38: =SUMPRODUCT(L21:L37,M21:M37)/M38 -> 982142.86 | M38: =SUM(M21:M37) -> 105
D40: Base Value 1 Bedroom Units | E40: =L32 -> 812500
D41: Base Value 2 Bedroom Units (base) | E41: 975000 | L41: updated - need to confimr pricing
D42: Base Value 3 Bedroom Units | E42: 1100000
B44: VERTICAL CONSTRUCTION
D46: Input Build Rate (psm) (incl GST) | E46: ='House Build Up'!C8 -> 3718.6475 | J46: Proposed starting uint pricing
D47: Sensitivity | E47: 0
D48: Applied Build Rate (psm) (incl GST) | E48: =E46*(1+E47) -> 3718.6475
D49: Apartment Premium | E49: 0.4
C51: Costs
...

Sheet Model Inputs
B2: GENERAL
D4: Model Commencement Date | E4: 46203 | F4: placeholder for XIRR
D6: Model Term | E6: 15 | F6: years
D7: Periodicity | E7: 12 | F7: 1 = annually; 2 = biannually; 4 = quarterly; 12 = monthly
B10: STRUCTURE
C12: Share Class Structure
D13: A Class | E13: 0.7
D14: B Class | E14: 0.3
C16: A Class Share Allocation
D17: Hāpai | E17: 1
D18: Vendor | E18: 0
C20: B Class Share Allocation
D21: Hāpai | E21: 0.5
D22: KPV | E22: 0.5
C24: Shareholdings
E25: Hāpai | F25: KPV | G25: =D18 -> Vendor | H25: Total
D26: A-Class | E26: =E13*E17 -> 0.7 | F26: 0 | G26: =E13*E18 -> 0 | H26: =SUM(E26:G26) -> 0.7
D27: B-Class | E27: =E21*E14 -> 0.15 | F27: =E22*E14 -> 0.15 | G27: 0 | H27: =SUM(E27:G27) -> 0.3
D28: Total | E28: =SUM(E26:E27) -> 0.85 | F28: =SUM(F26:F27) -> 0.15 | G28: =SUM(G26:G27) -> 0 | H28: =SUM(H26:H27) -> 1
C30: Preferred Interest (A-Class)
D31: Paid | E31: 0.045 | G31: Funder Choice - need spend on the opex
D32: Accrued | E32: 0.035
D33: Total | E33: =SUM(E31:E32) -> 0.08
B36: OPERATING
C38: Unit Turnover
D39: Average Resident Tenure | E39: 8 | F39: years | G39: 2 stages | H39: development | I39: longer | J39: 10-12
D40: Average DMF | E40: 0.24 | H40: steady state | J40: 8
D41: Resale Fee | E41: 0.01
C43: Turnover Scaling
D44: 1 | E44: 0
D45: =D44+1 -> 2 | E45: 0
D46: =D45+1 -> 3 | E46: 0
D47: =D46+1 -> 4 | E47: 0
D48: =D47+1 -> 5 | E48: 0.2 | G48: Updated as per recent investigation
D49: =D48+1 -> 6 | E49: 0.4
D50: =D49+1 -> 7 | E50: 0.6 | G50: complete
D51: =D50+1 -> 8 | E51: 0.8 | G51: complete
D52: =D51+1 -> 9 | E52: 1
D53: =D52+1 -> 10 | E53: 1
D54: =D53+1 -> 11 | E54: 1
...

Sheet Cashflow
D1: Period | J1: 1 | K1: 2 | L1: 3 | M1: 4 | N1: 5 | O1: 6 | P1: 7 | Q1: 8 | R1: 9 | S1: 10 | T1: 11 | U1: 12 | V1: 13 | W1: 14 | X1: 15 | Y1: 16 | Z1: 17 | AA1: 18 | AB1: 19 | AC1: 20 | AD1: 21 | AE1: 22 | AF1: 23 | AG1: 24 | AH1: 25 | AI1: 26 | AJ1: 27 | AK1: 28 | AL1: 29 | AM1: 30 | AN1: 31 | AO1: 32 | AP1: 33 | AQ1: 34 | AR1: 35 | AS1: 36 | AT1: 37 | AU1: 38 | AV1: 39 | AW1: 40 | AX1: 41 | AY1: 42 | AZ1: 43 | BA1: 44 | BB1: 45 | BC1: 46 | BD1: 47 | BE1: 48 | BF1: 49 | BG1: 50 | BH1: 51 | BI1: 52 | BJ1: 53 | BK1: 54 | BL1: 55 | BM1: 56 | BN1: 57 | BO1: 58 | BP1: 59 | BQ1: 60 | BR1: 61 | BS1: 62 | BT1: 63 | BU1: 64 | BV1: 65 | BW1: 66 | BX1: 67 | BY1: 68 | BZ1: 69 | CA1: 70 | CB1: 71 | CC1: 72 | CD1: 73 | CE1: 74 | CF1: 75 | CG1: 76 | CH1: 77 | CI1: 78 | CJ1: 79 | CK1: 80 | CL1: 81 | CM1: 82 | CN1: 83 | CO1: 84 | CP1: 85 | CQ1: 86 | CR1: 87 | CS1: 88 | CT1: 89 | CU1: 90 | CV1: 91 | CW1: 92 | CX1: 93 | CY1: 94 | CZ1: 95 | DA1: 96 | DB1: 97 | DC1: 98 | DD1: 99 | DE1: 100 | DF1: 101 | DG1: 102 | DH1: 103 | DI1: 104 | DJ1: 105 | DK1: 106 | DL1: 107 | DM1: 108 | DN1: 109 | DO1: 110 | DP1: 111 | DQ1: 112 | DR1: 113 | DS1: 114 | DT1: 115 | DU1: 116 | DV1: 117 | DW1: 118 | DX1: 119 | DY1: 120 | DZ1: 121 | EA1: 122 | EB1: 123 | EC1: 124 | ED1: 125 | EE1: 126 | EF1: 127 | EG1: 128 | EH1: 129 | EI1: 130 | EJ1: 131 | EK1: 132 | EL1: 133 | EM1: 134 | EN1: 135 | EO1: 136 | EP1: 137 | EQ1: 138 | ER1: 139 | ES1: 140 | ET1: 141 | EU1: 142 | EV1: 143 | EW1: 144 | EX1: 145 | EY1: 146 | EZ1: 147 | FA1: 148 | FB1: 149 | FC1: 150 | FD1: 151 | FE1: 152 | FF1: 153 | FG1: 154 | FH1: 155 | FI1: 156 | FJ1: 157 | FK1: 158 | FL1: 159 | FM1: 160 | FN1: 161 | FO1: 162 | FP1: 163 | FQ1: 164 | FR1: 165 | FS1: 166 | FT1: 167 | FU1: 168 | FV1: 169 | FW1: 170 | FX1: 171 | FY1: 172 | FZ1: 173 | GA1: 174 | GB1: 175 | GC1: 176 | GD1: 177 | GE1: 178 | GF1: 179 | GG1: 180
D2: Date | J2: ='Model Inputs'!E4 -> 46203 | K2: =EOMONTH(J2,12/Periodicity) -> 46234 | L2: =EOMONTH(K2,12/Periodicity) -> 46265 | M2: =EOMONTH(L2,12/Periodicity) -> 46295 | N2: =EOMONTH(M2,12/Periodicity) -> 46326 | O2: =EOMONTH(N2,12/Periodicity) -> 46356 | P2: =EOMONTH(O2,12/Periodicity) -> 46387 | Q2: =EOMONTH(P2,12/Periodicity) -> 46418 | R2: =EOMONTH(Q2,12/Periodicity) -> 46446 | ... GG2: =EOMONTH(GF2,12/Periodicity) -> 51652
D3: Development Phase | J3: =(SUM(J77:$GG$77)>0)*1 -> 1 | K3: =(SUM(K77:$GG$77)>0)*1 -> 1 | L3: =(SUM(L77:$GG$77)>0)*1 -> 1 | M3: =(SUM(M77:$GG$77)>0)*1 -> 1 | N3: =(SUM(N77:$GG$77)>0)*1 -> 1 | O3: =(SUM(O77:$GG$77)>0)*1 -> 1 | P3: =(SUM(P77:$GG$77)>0)*1 -> 1 | Q3: =(SUM(Q77:$GG$77)>0)*1 -> 1 | ... GG3: =(SUM(GG77:$GG$77)>0)*1 -> 0
D4: Operating Phase | J4: =(J3=0)*1 -> 0 | K4: =(K3=0)*1 -> 0 | L4: =(L3=0)*1 -> 0 | M4: =(M3=0)*1 -> 0 | N4: =(N3=0)*1 -> 0 | O4: =(O3=0)*1 -> 0 | P4: =(P3=0)*1 -> 0 | Q4: =(Q3=0)*1 -> 0 | ... GG4: =(GG3=0)*1 -> 1
D5: Project Year | J5: =ROUNDUP(SUM($J3:J4)/Periodicity,0) -> 1 | K5: =ROUNDUP(SUM($J3:K4)/Periodicity,0) -> 1 | L5: =ROUNDUP(SUM($J3:L4)/Periodicity,0) -> 1 | M5: =ROUNDUP(SUM($J3:M4)/Periodicity,0) -> 1 | N5: =ROUNDUP(SUM($J3:N4)/Periodicity,0) -> 1 | O5: =ROUNDUP(SUM($J3:O4)/Periodicity,0) -> 1 | P5: =ROUNDUP(SUM($J3:P4)/Periodicity,0) -> 1 | Q5: =ROUNDUP(SUM($J3:Q4)/Periodicity,0) -> 1 | ... GG5: =ROUNDUP(SUM($J3:GG4)/Periodicity,0) -> 15
D6: Operating Year | J6: =ROUNDUP(SUM($J4:J4)/Periodicity,0) -> 0 | K6: =ROUNDUP(SUM($J4:K4)/Periodicity,0) -> 0 | L6: =ROUNDUP(SUM($J4:L4)/Periodicity,0) -> 0 | M6: =ROUNDUP(SUM($J4:M4)/Periodicity,0) -> 0 | N6: =ROUNDUP(SUM($J4:N4)/Periodicity,0) -> 0 | O6: =ROUNDUP(SUM($J4:O4)/Periodicity,0) -> 0 | P6: =ROUNDUP(SUM($J4:P4)/Periodicity,0) -> 0 | Q6: =ROUNDUP(SUM($J4:Q4)/Periodicity,0) -> 0 | ... GG6: =ROUNDUP(SUM($J4:GG4)/Periodicity,0) -> 10
D8: Inflation Factor - Capital Growth | J8: =(1+'Model Inputs'!$E$66)^(J$5-1) -> 1 | K8: =(1+'Model Inputs'!$E$66)^(K$5-1) -> 1 | L8: =(1+'Model Inputs'!$E$66)^(L$5-1) -> 1 | M8: =(1+'Model Inputs'!$E$66)^(M$5-1) -> 1 | N8: =(1+'Model Inputs'!$E$66)^(N$5-1) -> 1 | O8: =(1+'Model Inputs'!$E$66)^(O$5-1) -> 1 | P8: =(1+'Model Inputs'!$E$66)^(P$5-1) -> 1 | Q8: =(1+'Model Inputs'!$E$66)^(Q$5-1) -> 1 | ... GG8: =(1+'Model Inputs'!$E$66)^(GG$5-1) -> 1.3194788
D9: Inflation Factor - Costs | J9: =(1+'Model Inputs'!$E$67)^(J$5-1) -> 1 | K9: =(1+'Model Inputs'!$E$67)^(K$5-1) -> 1 | L9: =(1+'Model Inputs'!$E$67)^(L$5-1) -> 1 | M9: =(1+'Model Inputs'!$E$67)^(M$5-1) -> 1 | N9: =(1+'Model Inputs'!$E$67)^(N$5-1) -> 1 | O9: =(1+'Model Inputs'!$E$67)^(O$5-1) -> 1 | P9: =(1+'Model Inputs'!$E$67)^(P$5-1) -> 1 | Q9: =(1+'Model Inputs'!$E$67)^(Q$5-1) -> 1 | ... GG9: =(1+'Model Inputs'!$E$67)^(GG$5-1) -> 1.3194788
D10: Inflation Factor - Lease | J10: =(1+'Model Inputs'!$E$68)^(J$5-1) -> 1 | K10: =(1+'Model Inputs'!$E$68)^(K$5-1) -> 1 | L10: =(1+'Model Inputs'!$E$68)^(L$5-1) -> 1 | M10: =(1+'Model Inputs'!$E$68)^(M$5-1) -> 1 | N10: =(1+'Model Inputs'!$E$68)^(N$5-1) -> 1 | O10: =(1+'Model Inputs'!$E$68)^(O$5-1) -> 1 | P10: =(1+'Model Inputs'!$E$68)^(P$5-1) -> 1 | Q10: =(1+'Model Inputs'!$E$68)^(Q$5-1) -> 1 | ... GG10: =(1+'Model Inputs'!$E$68)^(GG$5-1) -> 1.3194788
B13: TIMING
C15: Land Development - Stages & Allocation | E15: Allocation | G15: Commencement | H15: Duration
D16: ='Project Inputs'!D175 -> Stage 1 | E16: ='Project Inputs'!G175 -> 0.4 | G16: ='Project Inputs'!E175 -> 6 | H16: ='Project Inputs'!F175 -> 8 | J16: =IF($E16=0,0,AND(J$1>=$G16,J$1<SUM($G16:$H16))*($E16/$H16)) -> 0 | K16: =IF($E16=0,0,AND(K$1>=$G16,K$1<SUM($G16:$H16))*($E16/$H16)) -> 0 | L16: =IF($E16=0,0,AND(L$1>=$G16,L$1<SUM($G16:$H16))*($E16/$H16)) -> 0 | M16: =IF($E16=0,0,AND(M$1>=$G16,M$1<SUM($G16:$H16))*($E16/$H16)) -> 0 | N16: =IF($E16=0,0,AND(N$1>=$G16,N$1<SUM($G16:$H16))*($E16/$H16)) -> 0 | O16: =IF($E16=0,0,AND(O$1>=$G16,O$1<SUM($G16:$H16))*($E16/$H16)) -> 0.05 | P16: =IF($E16=0,0,AND(P$1>=$G16,P$1<SUM($G16:$H16))*($E16/$H16)) -> 0.05 | Q16: =IF($E16=0,0,AND(Q$1>=$G16,Q$1<SUM($G16:$H16))*($E16/$H16)) -> 0.05 | ... GG16: =IF($E16=0,0,AND(GG$1>=$G16,GG$1<SUM($G16:$H16))*($E16/$H16)) -> 0
D17: ='Project Inputs'!D176 -> Stage 2 | E17: ='Project Inputs'!G176 -> 0.3 | G17: ='Project Inputs'!E176 -> 18 | H17: ='Project Inputs'!F176 -> 6 | J17: =IF($E17=0,0,AND(J$1>=$G17,J$1<SUM($G17:$H17))*($E17/$H17)) -> 0 | K17: =IF($E17=0,0,AND(K$1>=$G17,K$1<SUM($G17:$H17))*($E17/$H17)) -> 0 | L17: =IF($E17=0,0,AND(L$1>=$G17,L$1<SUM($G17:$H17))*($E17/$H17)) -> 0 | M17: =IF($E17=0,0,AND(M$1>=$G17,M$1<SUM($G17:$H17))*($E17/$H17)) -> 0 | N17: =IF($E17=0,0,AND(N$1>=$G17,N$1<SUM($G17:$H17))*($E17/$H17)) -> 0 | O17: =IF($E17=0,0,AND(O$1>=$G17,O$1<SUM($G17:$H17))*($E17/$H17)) -> 0 | P17: =IF($E17=0,0,AND(P$1>=$G17,P$1<SUM($G17:$H17))*($E17/$H17)) -> 0 | Q17: =IF($E17=0,0,AND(Q$1>=$G17,Q$1<SUM($G17:$H17))*($E17/$H17)) -> 0 | ... GG17: =IF($E17=0,0,AND(GG$1>=$G17,GG$1<SUM($G17:$H17))*($E17/$H17)) -> 0
D18: ='Project Inputs'!D177 -> Stage 3 | E18: ='Project Inputs'!G177 -> 0.3 | G18: ='Project Inputs'!E177 -> 30 | H18: ='Project Inputs'!F177 -> 6 | J18: =IF($E18=0,0,AND(J$1>=$G18,J$1<SUM($G18:$H18))*($E18/$H18)) -> 0 | K18: =IF($E18=0,0,AND(K$1>=$G18,K$1<SUM($G18:$H18))*($E18/$H18)) -> 0 | L18: =IF($E18=0,0,AND(L$1>=$G18,L$1<SUM($G18:$H18))*($E18/$H18)) -> 0 | M18: =IF($E18=0,0,AND(M$1>=$G18,M$1<SUM($G18:$H18))*($E18/$H18)) -> 0 | N18: =IF($E18=0,0,AND(N$1>=$G18,N$1<SUM($G18:$H18))*($E18/$H18)) -> 0 | O18: =IF($E18=0,0,AND(O$1>=$G18,O$1<SUM($G18:$H18))*($E18/$H18)) -> 0 | P18: =IF($E18=0,0,AND(P$1>=$G18,P$1<SUM($G18:$H18))*($E18/$H18)) -> 0 | Q18: =IF($E18=0,0,AND(Q$1>=$G18,Q$1<SUM($G18:$H18))*($E18/$H18)) -> 0 | ... GG18: =IF($E18=0,0,AND(GG$1>=$G18,GG$1<SUM($G18:$H18))*($E18/$H18)) -> 0
D19: ='Project Inputs'!D178 -> Stage 4 | E19: ='Project Inputs'!G178 -> 0 | G19: ='Project Inputs'!E178 -> 0 | H19: ='Project Inputs'!F178 -> 0 | J19: =IF($E19=0,0,AND(J$1>=$G19,J$1<SUM($G19:$H19))*($E19/$H19)) -> 0 | K19: =IF($E19=0,0,AND(K$1>=$G19,K$1<SUM($G19:$H19))*($E19/$H19)) -> 0 | L19: =IF($E19=0,0,AND(L$1>=$G19,L$1<SUM($G19:$H19))*($E19/$H19)) -> 0 | M19: =IF($E19=0,0,AND(M$1>=$G19,M$1<SUM($G19:$H19))*($E19/$H19)) -> 0 | N19: =IF($E19=0,0,AND(N$1>=$G19,N$1<SUM($G19:$H19))*($E19/$H19)) -> 0 | O19: =IF($E19=0,0,AND(O$1>=$G19,O$1<SUM($G19:$H19))*($E19/$H19)) -> 0 | P19: =IF($E19=0,0,AND(P$1>=$G19,P$1<SUM($G19:$H19))*($E19/$H19)) -> 0 | Q19: =IF($E19=0,0,AND(Q$1>=$G19,Q$1<SUM($G19:$H19))*($E19/$H19)) -> 0 | ... GG19: =IF($E19=0,0,AND(GG$1>=$G19,GG$1<SUM($G19:$H19))*($E19/$H19)) -> 0
D20: ='Project Inputs'!D179 -> Stage 5 | E20: ='Project Inputs'!G179 -> 0 | G20: ='Project Inputs'!E179 -> 0 | H20: ='Project Inputs'!F179 -> 0 | J20: =IF($E20=0,0,AND(J$1>=$G20,J$1<SUM($G20:$H20))*($E20/$H20)) -> 0 | K20: =IF($E20=0,0,AND(K$1>=$G20,K$1<SUM($G20:$H20))*($E20/$H20)) -> 0 | L20: =IF($E20=0,0,AND(L$1>=$G20,L$1<SUM($G20:$H20))*($E20/$H20)) -> 0 | M20: =IF($E20=0,0,AND(M$1>=$G20,M$1<SUM($G20:$H20))*($E20/$H20)) -> 0 | N20: =IF($E20=0,0,AND(N$1>=$G20,N$1<SUM($G20:$H20))*($E20/$H20)) -> 0 | O20: =IF($E20=0,0,AND(O$1>=$G20,O$1<SUM($G20:$H20))*($E20/$H20)) -> 0 | P20: =IF($E20=0,0,AND(P$1>=$G20,P$1<SUM($G20:$H20))*($E20/$H20)) -> 0 | Q20: =IF($E20=0,0,AND(Q$1>=$G20,Q$1<SUM($G20:$H20))*($E20/$H20)) -> 0 | ... GG20: =IF($E20=0,0,AND(GG$1>=$G20,GG$1<SUM($G20:$H20))*($E20/$H20)) -> 0
J21: =SUM(J16:J20) -> 0 | K21: =SUM(K16:K20) -> 0 | L21: =SUM(L16:L20) -> 0 | M21: =SUM(M16:M20) -> 0 | N21: =SUM(N16:N20) -> 0 | O21: =SUM(O16:O20) -> 0.05 | P21: =SUM(P16:P20) -> 0.05 | Q21: =SUM(Q16:Q20) -> 0.05 | ... GG21: =SUM(GG16:GG20) -> 0
C23: Vertical Construction - Timing | G23: Commencement | H23: Duration
D24: {=_xlfn.SEQUENCE('Project Inputs'!$E$190)} -> 1 | G24: ='Project Inputs'!E183*(D24>0) -> 16 | H24: ='Project Inputs'!$E$184*(D24>0) -> 3 | J24: =AND(J$1>=$G24,J$1<SUM($G24:$H24))*1 -> 0 | K24: =AND(K$1>=$G24,K$1<SUM($G24:$H24))*1 -> 0 | L24: =AND(L$1>=$G24,L$1<SUM($G24:$H24))*1 -> 0 | M24: =AND(M$1>=$G24,M$1<SUM($G24:$H24))*1 -> 0 | N24: =AND(N$1>=$G24,N$1<SUM($G24:$H24))*1 -> 0 | O24: =AND(O$1>=$G24,O$1<SUM($G24:$H24))*1 -> 0 | P24: =AND(P$1>=$G24,P$1<SUM($G24:$H24))*1 -> 0 | Q24: =AND(Q$1>=$G24,Q$1<SUM($G24:$H24))*1 -> 0 | ... GG24: =AND(GG$1>=$G24,GG$1<SUM($G24:$H24))*1 -> 0
D25: 2 | G25: =(G24+'Project Inputs'!$E$185)*(D25>0) -> 19 | H25: ='Project Inputs'!$E$184*(D25>0) -> 3 | J25: =AND(J$1>=$G25,J$1<SUM($G25:$H25))*1 -> 0 | K25: =AND(K$1>=$G25,K$1<SUM($G25:$H25))*1 -> 0 | L25: =AND(L$1>=$G25,L$1<SUM($G25:$H25))*1 -> 0 | M25: =AND(M$1>=$G25,M$1<SUM($G25:$H25))*1 -> 0 | N25: =AND(N$1>=$G25,N$1<SUM($G25:$H25))*1 -> 0 | O25: =AND(O$1>=$G25,O$1<SUM($G25:$H25))*1 -> 0 | P25: =AND(P$1>=$G25,P$1<SUM($G25:$H25))*1 -> 0 | Q25: =AND(Q$1>=$G25,Q$1<SUM($G25:$H25))*1 -> 0 | ... GG25: =AND(GG$1>=$G25,GG$1<SUM($G25:$H25))*1 -> 0
D26: 3 | G26: =(G25+'Project Inputs'!$E$185)*(D26>0) -> 22 | H26: ='Project Inputs'!$E$184*(D26>0) -> 3 | J26: =AND(J$1>=$G26,J$1<SUM($G26:$H26))*1 -> 0 | K26: =AND(K$1>=$G26,K$1<SUM($G26:$H26))*1 -> 0 | L26: =AND(L$1>=$G26,L$1<SUM($G26:$H26))*1 -> 0 | M26: =AND(M$1>=$G26,M$1<SUM($G26:$H26))*1 -> 0 | N26: =AND(N$1>=$G26,N$1<SUM($G26:$H26))*1 -> 0 | O26: =AND(O$1>=$G26,O$1<SUM($G26:$H26))*1 -> 0 | P26: =AND(P$1>=$G26,P$1<SUM($G26:$H26))*1 -> 0 | Q26: =AND(Q$1>=$G26,Q$1<SUM($G26:$H26))*1 -> 0 | ... GG26: =AND(GG$1>=$G26,GG$1<SUM($G26:$H26))*1 -> 0
D27: 4 | G27: =(G26+'Project Inputs'!$E$185)*(D27>0) -> 25 | H27: ='Project Inputs'!$E$184*(D27>0) -> 3 | J27: =AND(J$1>=$G27,J$1<SUM($G27:$H27))*1 -> 0 | K27: =AND(K$1>=$G27,K$1<SUM($G27:$H27))*1 -> 0 | L27: =AND(L$1>=$G27,L$1<SUM($G27:$H27))*1 -> 0 | M27: =AND(M$1>=$G27,M$1<SUM($G27:$H27))*1 -> 0 | N27: =AND(N$1>=$G27,N$1<SUM($G27:$H27))*1 -> 0 | O27: =AND(O$1>=$G27,O$1<SUM($G27:$H27))*1 -> 0 | P27: =AND(P$1>=$G27,P$1<SUM($G27:$H27))*1 -> 0 | Q27: =AND(Q$1>=$G27,Q$1<SUM($G27:$H27))*1 -> 0 | ... GG27: =AND(GG$1>=$G27,GG$1<SUM($G27:$H27))*1 -> 0
D28: 5 | G28: =(G27+'Project Inputs'!$E$185)*(D28>0) -> 28 | H28: ='Project Inputs'!$E$184*(D28>0) -> 3 | J28: =AND(J$1>=$G28,J$1<SUM($G28:$H28))*1 -> 0 | K28: =AND(K$1>=$G28,K$1<SUM($G28:$H28))*1 -> 0 | L28: =AND(L$1>=$G28,L$1<SUM($G28:$H28))*1 -> 0 | M28: =AND(M$1>=$G28,M$1<SUM($G28:$H28))*1 -> 0 | N28: =AND(N$1>=$G28,N$1<SUM($G28:$H28))*1 -> 0 | O28: =AND(O$1>=$G28,O$1<SUM($G28:$H28))*1 -> 0 | P28: =AND(P$1>=$G28,P$1<SUM($G28:$H28))*1 -> 0 | Q28: =AND(Q$1>=$G28,Q$1<SUM($G28:$H28))*1 -> 0 | ... GG28: =AND(GG$1>=$G28,GG$1<SUM($G28:$H28))*1 -> 0
D29: 6 | G29: =(G28+'Project Inputs'!$E$185)*(D29>0) -> 31 | H29: ='Project Inputs'!$E$184*(D29>0) -> 3 | J29: =AND(J$1>=$G29,J$1<SUM($G29:$H29))*1 -> 0 | K29: =AND(K$1>=$G29,K$1<SUM($G29:$H29))*1 -> 0 | L29: =AND(L$1>=$G29,L$1<SUM($G29:$H29))*1 -> 0 | M29: =AND(M$1>=$G29,M$1<SUM($G29:$H29))*1 -> 0 | N29: =AND(N$1>=$G29,N$1<SUM($G29:$H29))*1 -> 0 | O29: =AND(O$1>=$G29,O$1<SUM($G29:$H29))*1 -> 0 | P29: =AND(P$1>=$G29,P$1<SUM($G29:$H29))*1 -> 0 | Q29: =AND(Q$1>=$G29,Q$1<SUM($G29:$H29))*1 -> 0 | ... GG29: =AND(GG$1>=$G29,GG$1<SUM($G29:$H29))*1 -> 0
D30: 7 | G30: =(G29+'Project Inputs'!$E$185)*(D30>0) -> 34 | H30: ='Project Inputs'!$E$184*(D30>0) -> 3 | J30: =AND(J$1>=$G30,J$1<SUM($G30:$H30))*1 -> 0 | K30: =AND(K$1>=$G30,K$1<SUM($G30:$H30))*1 -> 0 | L30: =AND(L$1>=$G30,L$1<SUM($G30:$H30))*1 -> 0 | M30: =AND(M$1>=$G30,M$1<SUM($G30:$H30))*1 -> 0 | N30: =AND(N$1>=$G30,N$1<SUM($G30:$H30))*1 -> 0 | O30: =AND(O$1>=$G30,O$1<SUM($G30:$H30))*1 -> 0 | P30: =AND(P$1>=$G30,P$1<SUM($G30:$H30))*1 -> 0 | Q30: =AND(Q$1>=$G30,Q$1<SUM($G30:$H30))*1 -> 0 | ... GG30: =AND(GG$1>=$G30,GG$1<SUM($G30:$H30))*1 -> 0
D31: 8 | G31: =(G30+'Project Inputs'!$E$185)*(D31>0) -> 37 | H31: ='Project Inputs'!$E$184*(D31>0) -> 3 | J31: =AND(J$1>=$G31,J$1<SUM($G31:$H31))*1 -> 0 | K31: =AND(K$1>=$G31,K$1<SUM($G31:$H31))*1 -> 0 | L31: =AND(L$1>=$G31,L$1<SUM($G31:$H31))*1 -> 0 | M31: =AND(M$1>=$G31,M$1<SUM($G31:$H31))*1 -> 0 | N31: =AND(N$1>=$G31,N$1<SUM($G31:$H31))*1 -> 0 | O31: =AND(O$1>=$G31,O$1<SUM($G31:$H31))*1 -> 0 | P31: =AND(P$1>=$G31,P$1<SUM($G31:$H31))*1 -> 0 | Q31: =AND(Q$1>=$G31,Q$1<SUM($G31:$H31))*1 -> 0 | ... GG31: =AND(GG$1>=$G31,GG$1<SUM($G31:$H31))*1 -> 0
D32: 9 | G32: =(G31+'Project Inputs'!$E$185)*(D32>0) -> 40 | H32: ='Project Inputs'!$E$184*(D32>0) -> 3 | J32: =AND(J$1>=$G32,J$1<SUM($G32:$H32))*1 -> 0 | K32: =AND(K$1>=$G32,K$1<SUM($G32:$H32))*1 -> 0 | L32: =AND(L$1>=$G32,L$1<SUM($G32:$H32))*1 -> 0 | M32: =AND(M$1>=$G32,M$1<SUM($G32:$H32))*1 -> 0 | N32: =AND(N$1>=$G32,N$1<SUM($G32:$H32))*1 -> 0 | O32: =AND(O$1>=$G32,O$1<SUM($G32:$H32))*1 -> 0 | P32: =AND(P$1>=$G32,P$1<SUM($G32:$H32))*1 -> 0 | Q32: =AND(Q$1>=$G32,Q$1<SUM($G32:$H32))*1 -> 0 | ... GG32: =AND(GG$1>=$G32,GG$1<SUM($G32:$H32))*1 -> 0
D33: 10 | G33: =(G32+'Project Inputs'!$E$185)*(D33>0) -> 43 | H33: ='Project Inputs'!$E$184*(D33>0) -> 3 | J33: =AND(J$1>=$G33,J$1<SUM($G33:$H33))*1 -> 0 | K33: =AND(K$1>=$G33,K$1<SUM($G33:$H33))*1 -> 0 | L33: =AND(L$1>=$G33,L$1<SUM($G33:$H33))*1 -> 0 | M33: =AND(M$1>=$G33,M$1<SUM($G33:$H33))*1 -> 0 | N33: =AND(N$1>=$G33,N$1<SUM($G33:$H33))*1 -> 0 | O33: =AND(O$1>=$G33,O$1<SUM($G33:$H33))*1 -> 0 | P33: =AND(P$1>=$G33,P$1<SUM($G33:$H33))*1 -> 0 | Q33: =AND(Q$1>=$G33,Q$1<SUM($G33:$H33))*1 -> 0 | ... GG33: =AND(GG$1>=$G33,GG$1<SUM($G33:$H33))*1 -> 0
D34: 11 | G34: =(G33+'Project Inputs'!$E$185)*(D34>0) -> 46 | H34: ='Project Inputs'!$E$184*(D34>0) -> 3 | J34: =AND(J$1>=$G34,J$1<SUM($G34:$H34))*1 -> 0 | K34: =AND(K$1>=$G34,K$1<SUM($G34:$H34))*1 -> 0 | L34: =AND(L$1>=$G34,L$1<SUM($G34:$H34))*1 -> 0 | M34: =AND(M$1>=$G34,M$1<SUM($G34:$H34))*1 -> 0 | N34: =AND(N$1>=$G34,N$1<SUM($G34:$H34))*1 -> 0 | O34: =AND(O$1>=$G34,O$1<SUM($G34:$H34))*1 -> 0 | P34: =AND(P$1>=$G34,P$1<SUM($G34:$H34))*1 -> 0 | Q34: =AND(Q$1>=$G34,Q$1<SUM($G34:$H34))*1 -> 0 | ... GG34: =AND(GG$1>=$G34,GG$1<SUM($G34:$H34))*1 -> 0
D35: 12 | G35: =(G34+'Project Inputs'!$E$185)*(D35>0) -> 49 | H35: ='Project Inputs'!$E$184*(D35>0) -> 3 | J35: =AND(J$1>=$G35,J$1<SUM($G35:$H35))*1 -> 0 | K35: =AND(K$1>=$G35,K$1<SUM($G35:$H35))*1 -> 0 | L35: =AND(L$1>=$G35,L$1<SUM($G35:$H35))*1 -> 0 | M35: =AND(M$1>=$G35,M$1<SUM($G35:$H35))*1 -> 0 | N35: =AND(N$1>=$G35,N$1<SUM($G35:$H35))*1 -> 0 | O35: =AND(O$1>=$G35,O$1<SUM($G35:$H35))*1 -> 0 | P35: =AND(P$1>=$G35,P$1<SUM($G35:$H35))*1 -> 0 | Q35: =AND(Q$1>=$G35,Q$1<SUM($G35:$H35))*1 -> 0 | ... GG35: =AND(GG$1>=$G35,GG$1<SUM($G35:$H35))*1 -> 0
D36: 13 | G36: =(G35+'Project Inputs'!$E$185)*(D36>0) -> 52 | H36: ='Project Inputs'!$E$184*(D36>0) -> 3 | J36: =AND(J$1>=$G36,J$1<SUM($G36:$H36))*1 -> 0 | K36: =AND(K$1>=$G36,K$1<SUM($G36:$H36))*1 -> 0 | L36: =AND(L$1>=$G36,L$1<SUM($G36:$H36))*1 -> 0 | M36: =AND(M$1>=$G36,M$1<SUM($G36:$H36))*1 -> 0 | N36: =AND(N$1>=$G36,N$1<SUM($G36:$H36))*1 -> 0 | O36: =AND(O$1>=$G36,O$1<SUM($G36:$H36))*1 -> 0 | P36: =AND(P$1>=$G36,P$1<SUM($G36:$H36))*1 -> 0 | Q36: =AND(Q$1>=$G36,Q$1<SUM($G36:$H36))*1 -> 0 | ... GG36: =AND(GG$1>=$G36,GG$1<SUM($G36:$H36))*1 -> 0
... D41: 18 | G41: =(G40+'Project Inputs'!$E$185)*(D41>0) -> 67 | H41: ='Project Inputs'!$E$184*(D41>0) -> 3 | J41: =AND(J$1>=$G41,J$1<SUM($G41:$H41))*1 -> 0 | K41: =AND(K$1>=$G41,K$1<SUM($G41:$H41))*1 -> 0 | L41: =AND(L$1>=$G41,L$1<SUM($G41:$H41))*1 -> 0 | M41: =AND(M$1>=$G41,M$1<SUM($G41:$H41))*1 -> 0 | N41: =AND(N$1>=$G41,N$1<SUM($G41:$H41))*1 -> 0 | O41: =AND(O$1>=$G41,O$1<SUM($G41:$H41))*1 -> 0 | P41: =AND(P$1>=$G41,P$1<SUM($G41:$H41))*1 -> 0 | Q41: =AND(Q$1>=$G41,Q$1<SUM($G41:$H41))*1 -> 0 | ... GG41: =AND(GG$1>=$G41,GG$1<SUM($G41:$H41))*1 -> 0
G42: =(G41+'Project Inputs'!$E$185)*(D42>0) -> 0 | H42: ='Project Inputs'!$E$184*(D42>0) -> 0 | J42: =AND(J$1>=$G42,J$1<SUM($G42:$H42))*1 -> 0 | K42: =AND(K$1>=$G42,K$1<SUM($G42:$H42))*1 -> 0 | L42: =AND(L$1>=$G42,L$1<SUM($G42:$H42))*1 -> 0 | M42: =AND(M$1>=$G42,M$1<SUM($G42:$H42))*1 -> 0 | N42: =AND(N$1>=$G42,N$1<SUM($G42:$H42))*1 -> 0 | O42: =AND(O$1>=$G42,O$1<SUM($G42:$H42))*1 -> 0 | P42: =AND(P$1>=$G42,P$1<SUM($G42:$H42))*1 -> 0 | Q42: =AND(Q$1>=$G42,Q$1<SUM($G42:$H42))*1 -> 0 | ... GG42: =AND(GG$1>=$G42,GG$1<SUM($G42:$H42))*1 -> 0
G43: =(G42+'Project Inputs'!$E$185)*(D43>0) -> 0 | H43: ='Project Inputs'!$E$184*(D43>0) -> 0 | J43: =AND(J$1>=$G43,J$1<SUM($G43:$H43))*1 -> 0 | K43: =AND(K$1>=$G43,K$1<SUM($G43:$H43))*1 -> 0 | L43: =AND(L$1>=$G43,L$1<SUM($G43:$H43))*1 -> 0 | M43: =AND(M$1>=$G43,M$1<SUM($G43:$H43))*1 -> 0 | N43: =AND(N$1>=$G43,N$1<SUM($G43:$H43))*1 -> 0 | O43: =AND(O$1>=$G43,O$1<SUM($G43:$H43))*1 -> 0 | P43: =AND(P$1>=$G43,P$1<SUM($G43:$H43))*1 -> 0 | Q43: =AND(Q$1>=$G43,Q$1<SUM($G43:$H43))*1 -> 0 | ... GG43: =AND(GG$1>=$G43,GG$1<SUM($G43:$H43))*1 -> 0
G44: =(G43+'Project Inputs'!$E$185)*(D44>0) -> 0 | H44: ='Project Inputs'!$E$184*(D44>0) -> 0 | J44: =AND(J$1>=$G44,J$1<SUM($G44:$H44))*1 -> 0 | K44: =AND(K$1>=$G44,K$1<SUM($G44:$H44))*1 -> 0 | L44: =AND(L$1>=$G44,L$1<SUM($G44:$H44))*1 -> 0 | M44: =AND(M$1>=$G44,M$1<SUM($G44:$H44))*1 -> 0 | N44: =AND(N$1>=$G44,N$1<SUM($G44:$H44))*1 -> 0 | O44: =AND(O$1>=$G44,O$1<SUM($G44:$H44))*1 -> 0 | P44: =AND(P$1>=$G44,P$1<SUM($G44:$H44))*1 -> 0 | Q44: =AND(Q$1>=$G44,Q$1<SUM($G44:$H44))*1 -> 0 | ... GG44: =AND(GG$1>=$G44,GG$1<SUM($G44:$H44))*1 -> 0
G45: =(G44+'Project Inputs'!$E$185)*(D45>0) -> 0 | H45: ='Project Inputs'!$E$184*(D45>0) -> 0 | J45: =AND(J$1>=$G45,J$1<SUM($G45:$H45))*1 -> 0 | K45: =AND(K$1>=$G45,K$1<SUM($G45:$H45))*1 -> 0 | L45: =AND(L$1>=$G45,L$1<SUM($G45:$H45))*1 -> 0 | M45: =AND(M$1>=$G45,M$1<SUM($G45:$H45))*1 -> 0 | N45: =AND(N$1>=$G45,N$1<SUM($G45:$H45))*1 -> 0 | O45: =AND(O$1>=$G45,O$1<SUM($G45:$H45))*1 -> 0 | P45: =AND(P$1>=$G45,P$1<SUM($G45:$H45))*1 -> 0 | Q45: =AND(Q$1>=$G45,Q$1<SUM($G45:$H45))*1 -> 0 | ... GG45: =AND(GG$1>=$G45,GG$1<SUM($G45:$H45))*1 -> 0
G46: =(G45+'Project Inputs'!$E$185)*(D46>0) -> 0 | H46: ='Project Inputs'!$E$184*(D46>0) -> 0 | J46: =AND(J$1>=$G46,J$1<SUM($G46:$H46))*1 -> 0 | K46: =AND(K$1>=$G46,K$1<SUM($G46:$H46))*1 -> 0 | L46: =AND(L$1>=$G46,L$1<SUM($G46:$H46))*1 -> 0 | M46: =AND(M$1>=$G46,M$1<SUM($G46:$H46))*1 -> 0 | N46: =AND(N$1>=$G46,N$1<SUM($G46:$H46))*1 -> 0 | O46: =AND(O$1>=$G46,O$1<SUM($G46:$H46))*1 -> 0 | P46: =AND(P$1>=$G46,P$1<SUM($G46:$H46))*1 -> 0 | Q46: =AND(Q$1>=$G46,Q$1<SUM($G46:$H46))*1 -> 0 | ... GG46: =AND(GG$1>=$G46,GG$1<SUM($G46:$H46))*1 -> 0
G47: =(G46+'Project Inputs'!$E$185)*(D47>0) -> 0 | H47: ='Project Inputs'!$E$184*(D47>0) -> 0 | J47: =AND(J$1>=$G47,J$1<SUM($G47:$H47))*1 -> 0 | K47: =AND(K$1>=$G47,K$1<SUM($G47:$H47))*1 -> 0 | L47: =AND(L$1>=$G47,L$1<SUM($G47:$H47))*1 -> 0 | M47: =AND(M$1>=$G47,M$1<SUM($G47:$H47))*1 -> 0 | N47: =AND(N$1>=$G47,N$1<SUM($G47:$H47))*1 -> 0 | O47: =AND(O$1>=$G47,O$1<SUM($G47:$H47))*1 -> 0 | P47: =AND(P$1>=$G47,P$1<SUM($G47:$H47))*1 -> 0 | Q47: =AND(Q$1>=$G47,Q$1<SUM($G47:$H47))*1 -> 0 | ... GG47: =AND(GG$1>=$G47,GG$1<SUM($G47:$H47))*1 -> 0
G48: =(G47+'Project Inputs'!$E$185)*(D48>0) -> 0 | H48: ='Project Inputs'!$E$184*(D48>0) -> 0 | J48: =AND(J$1>=$G48,J$1<SUM($G48:$H48))*1 -> 0 | K48: =AND(K$1>=$G48,K$1<SUM($G48:$H48))*1 -> 0 | L48: =AND(L$1>=$G48,L$1<SUM($G48:$H48))*1 -> 0 | M48: =AND(M$1>=$G48,M$1<SUM($G48:$H48))*1 -> 0 | N48: =AND(N$1>=$G48,N$1<SUM($G48:$H48))*1 -> 0 | O48: =AND(O$1>=$G48,O$1<SUM($G48:$H48))*1 -> 0 | P48: =AND(P$1>=$G48,P$1<SUM($G48:$H48))*1 -> 0 | Q48: =AND(Q$1>=$G48,Q$1<SUM($G48:$H48))*1 -> 0 | ... GG48: =AND(GG$1>=$G48,GG$1<SUM($G48:$H48))*1 -> 0
J49: =SUM(J24:J48) -> 0 | K49: =SUM(K24:K48) -> 0 | L49: =SUM(L24:L48) -> 0 | M49: =SUM(M24:M48) -> 0 | N49: =SUM(N24:N48) -> 0 | O49: =SUM(O24:O48) -> 0 | P49: =SUM(P24:P48) -> 0 | Q49: =SUM(Q24:Q48) -> 0 | ... GG49: =SUM(GG24:GG48) -> 0
...

Sheet Output
B2: KEY INPUTS & SENSITIVITY
C4: A Class Share Allocation
D5: Hāpai | E5: ='Model Inputs'!E17 -> 1 | F5: % of A-class shares
D6: ='Model Inputs'!D18 -> Vendor | E6: 0 | F6: % of A-class shares
C8: Land
D9: Model | E9: Operating Lease | F9: "Ownership" covers both freehold and pre-paid ground lease
E11: Per sqm | F11: Total
D12: Value (excl GST) | E12: 200 | F12: =E12*'Project Inputs'!$E$6 -> 9821800
D13: Value (incl GST) | E13: =E12*1.15 -> 230 | F13: =E13*'Project Inputs'!$E$6 -> 11295070
D15: Cap Rate | E15: ='Project Inputs'!E13 -> 0.06 | F15: only applicable to ground lease model
D16: Rental - annual (incl GST) | E16: =E15*F13 -> 677704.2
C18: Build Cost
D19: Input Build Rate (psm) (incl GST) | E19: ='Project Inputs'!E48 -> 3718.6475 | F19: base build rate (with premium applied for apartments where applicable)
C21: ORA Sales | I21: Area m2 | J21: m2 Sell
D22: Base Value 2 Bedroom Units | E22: ='Project Inputs'!E41 -> 975000 | I22: 122 | J22: =E22/122 -> 7991.8033
D23: Base Value 3 Bedroom Units | E23: ='Project Inputs'!E42 -> 1100000 | F23: all units valued in proportion to base value | I23: 144 | J23: =E23/144 -> 7638.8889
D24: Average Value (incl GST) | E24: ='Project Inputs'!L38 -> 982142.86 | F24: average will vary based on proposed delivery mix
C26: Growth & Inflation
D27: Capital Growth | E27: ='Model Inputs'!E66 -> 0.02 | F27: applicable to ORA sales and unit turnover income
D28: Inflation - Costs | E28: ='Model Inputs'!E67 -> 0.02 | F28: applicable to development costs
D29: Inflation - Lease | E29: ='Model Inputs'!E68 -> 0.02 | F29: applicable to operating lease
B32: ORA SURPLUS
D34: ORA Sales | E34: =SUM(Cashflow!J125:GG125)/1000 -> 103125
D35: Inflation - ORA | E35: =SUM(Cashflow!J126:GG126)/1000 -> 6720.4703 | F35: increase in values during development - highlighted as separate item for transparency
E36: =SUM(E34:E35) -> 109845.47
D38: Land | E38: =SUM(Cashflow!J111:GG111)/-1000 -> 0
D39: Ground Lease | E39: =SUM(Cashflow!J112:GG112)/-1000 -> 3896.7992
D40: Preliminary Costs | E40: =SUM(Cashflow!J113:GG113)/-1000 -> 4022.5
D41: Land Development | E41: =SUM(Cashflow!J114:GG114)/-1000 -> 13248.789
D42: Vertical Construction | E42: =SUM(Cashflow!J115:GG115)/-1000 -> 47818.832
D43: Community Centre | E43: =SUM(Cashflow!J116:GG116)/-1000 -> 7662.1977
D44: Holding & Other | E44: =SUM(Cashflow!J117:GG117)/-1000 -> 2491.725
D45: KPV Processing Fee | E45: =SUM(Cashflow!J118:GG118)/-1000 -> 1128.6607
D46: KPV Transaction Fee | E46: =SUM(Cashflow!J119:GG119)/-1000 -> 865.39114
D47: KPV Management Fee | E47: =SUM(Cashflow!J120:GG120)/-1000 -> 1725
D48: Inflation - Cost | E48: =SUM(Cashflow!J121:GG121)/-1000 -> 3751.1493 | F48: cost inflation during development - highlighted as separate item for transparency
E49: =SUM(E38:E48) -> 86611.044
D51: Surplus Pre-Preferred | E51: =E36-E49 -> 23234.426 | F51: =E51/$E$34 -> 0.22530353
D53: Preferred Interest | E53: =SUM(Cashflow!J122:CC122)/-1000 -> 5250.6435 | F53: in 6 Years of Development | K53: Preferred Interest; Ownership | M53: 11251.331 | N53: Copy and paste for lease ORA surplus scenario
K54: Preferred Interest: Formula Driven | M54: =SUM(Cashflow!J122:GG122)/-1000 -> 5250.6435 | N54: For comparison/to maintain back up
...

Sheet Village Valuation
B2: VILLAGE VALUATION ON COMPLETION
B6: VILLAGE OVERVIEW
B8: Village Characteristics | E8: Value | F8: Notes
B9: Total Units | E9: 105 | F9: Independent living units
B10: Land Area (sqm) | E10: ='Project Inputs'!E6 -> 49109 | F10: Total site area
B11: Village Star Rating | E11: ='Project Inputs'!E103 -> 4.5
B12: Community Centre (sqm) | E12: 925 | F12: Pool, gym, dining, games, admin
B13: Average Resident Tenure | E13: ='Model Inputs'!E39 -> 8
B14: Deferred Management Fee (DMF) | E14: ='Model Inputs'!E40 -> 0.24
B15: Resale Fee | E15: ='Model Inputs'!E41 -> 0.01
B17: Unit Mix Summary | D17: Typology | E17: Qty | F17: ORA Value | G17: Total Value
B18: BSG — 2 Bed Duplex (SG) | D18: House | E18: 50 | F18: ='Project Inputs'!E41 -> 975000 | G18: =E18*F18 -> 48750000
B19: MNSG — 3 Bed Duplex (SG) | D19: House | E19: 30 | F19: ='Project Inputs'!E42 -> 1100000 | G19: =E19*F19 -> 33000000
B20: R6 — 1 Bed (Six-Unit Block) | D20: House | E20: 20 | F20: 750000 | G20: =E20*F20 -> 15000000
B21: Total / Weighted Average | E21: =SUM(E18:E20) -> 100 | F21: =G21/E21 -> 967500 | G21: =SUM(G18:G20) -> 96750000
B23: TOTAL DEVELOPMENT COST
B25: Development Cost Build-Up | E25: $000s | F25: % of Total | G25: $/Unit
B26: Land (incl GST) | E26: =Output!F13/1000 -> 11295.07 | F26: =E26/$E$36 -> 0.11536634 | G26: =E26*1000/E21 -> 112950.7
B27: Ground Lease (development period) | E27: =Output!E39 -> 3896.7992 | F27: =E27/$E$36 -> 0.039801387 | G27: =E27*1000/E21 -> 38967.992
B28: Preliminary Costs | E28: =Output!E40 -> 4022.5 | F28: =E28/$E$36 -> 0.041085279 | G28: =E28*1000/E21 -> 40225
B29: Land Development | E29: =Output!E41 -> 13248.789 | F29: =E29/$E$36 -> 0.13532136 | G29: =E29*1000/E21 -> 132487.89
B30: Vertical Construction | E30: =Output!E42 -> 47818.832 | F30: =E30/$E$36 -> 0.48841518 | G30: =E30*1000/E21 -> 478188.32
B31: Community Centre | E31: =Output!E43 -> 7662.1977 | F31: =E31/$E$36 -> 0.078260666 | G31: =E31*1000/E21 -> 76621.977
B32: Holding & Other Costs | E32: =Output!E44 -> 2491.725 | F32: =E32/$E$36 -> 0.025450147 | G32: =E32*1000/E21 -> 24917.25
B33: KPV Fees (Processing + Transaction + Mgmt) | E33: =Output!E45+Output!E46+Output!E47 -> 3719.0518 | F33: =E33/$E$36 -> 0.037985899 | G33: =E33*1000/E21 -> 37190.518
B34: Cost Inflation (during development) | E34: =Output!E48 -> 3751.1493 | F34: =E34/$E$36 -> 0.038313739 | G34: =E34*1000/E21 -> 37511.493
B36: Total Development Cost | E36: =SUM(E26:E34) -> 97906.114 | F36: =E36/$E$36 -> 1 | G36: =E36*1000/E21 -> 979061.14
B38: INCOME APPROACH — DISCOUNTED CASH FLOW
B40: Valuation Assumptions | E40: Assumption | F40: Source / Notes
B41: Average ORA Value (Day 1) | E41: =F21 -> 967500 | F41: Weighted average across unit mix
B42: Total ORA Portfolio Value (Day 1, $000s) | E42: =G21/1000 -> 96750 | F42: 100 units × average ORA
B43: Capital Growth Rate (p.a.) | E43: ='Model Inputs'!E66 -> 0.02 | F43: Applied to ORA values and turnover income
B44: Average Resident Tenure | E44: =E13 -> 8 | F44: Implies ~12.5% annual unit turnover at maturity
B45: DMF Retained on Turnover | E45: =E14 -> 0.24 | F45: Deferred management fee
B46: Resale Commission | E46: =E15 -> 0.01 | F46: Agent / marketing fee on resale
B47: Net Margin on Turnover | E47: =E45-E46 -> 0.23 | F47: DMF less resale costs = net operator margin
B48: Discount Rate (Terminal Value) | E48: ='Model Inputs'!E61 -> 0.175 | F48: Applied to capitalise stabilised cashflows
B50: Stabilised Annual Income ($000s) | E50: $000s | F50: Notes
B51: Unit Turnover Income (at maturity) | E51: =Output!H80-Cashflow!GG171*12/1000 -> 3912.0484 | F51: DMF income from unit resales at full churn
B52: Less: Ground Lease Rental | E52: =Cashflow!GG171*12/1000 -> -894.2163 | F52: Annual lease cost (if operating lease model)
...

Sheet House Build Up
A1: Design | C1: 3500
A2: Consenting | C2: 10000
A3: Laterals/ drainage | C3: 15000
A4: House | B4: 3000 | C4: =B4*122 -> 366000
C5: =C4+C3+C2+C1 -> 394500
B6: 122 | C6: =C5/B6 -> 3233.6066
B7: GST | C7: =C6*15% -> 485.04098
C8: =C7+C6 -> 3718.6475

Sheet For Slides - Freehold
B2: Formula Driven: | L2: Formula Driven:
C4: Freehold | F4: Leasehold | I4: Variance | M4: 25% Vendor Share | R4: 50% Vendor Share
C6: A Class | D6: B Class | F6: A Class | G6: B Class | I6: A Class | J6: B Class | M6: Hāpai | N6: KPV | O6: Vendor | P6: Total | R6: Hāpai | S6: KPV | T6: Vendor | U6: Total
B7: Shareholdings | L7: Shareholdings
B8: A-Class | C8: =Output!J62 -> 0.7 | D8: =Output!K62 -> 0 | F8: =Output!J62 -> 0.7 | G8: =Output!K62 -> 0 | I8: =C8-F8 -> 0 | J8: =D8-G8 -> 0 | L8: A-Class | M8: =Output!E62 -> 0.7 | N8: =Output!F62 -> 0 | O8: =Output!G62 -> 0 | P8: =Output!H62 -> 0.7 | R8: =Output!E62 -> 0.7 | S8: =Output!F62 -> 0 | T8: =Output!G62 -> 0 | U8: =Output!H62 -> 0.7
B9: B-Class | C9: =Output!J63 -> 0 | D9: =Output!K63 -> 0.3 | F9: =Output!J63 -> 0 | G9: =Output!K63 -> 0.3 | I9: =C9-F9 -> 0 | J9: =D9-G9 -> 0 | L9: B-Class | M9: =Output!E63 -> 0.15 | N9: =Output!F63 -> 0.15 | O9: =Output!G63 -> 0 | P9: =Output!H63 -> 0.3 | R9: =Output!E63 -> 0.15 | S9: =Output!F63 -> 0.15 | T9: =Output!G63 -> 0 | U9: =Output!H63 -> 0.3
B10: Total | C10: =Output!J64 -> 0.7 | D10: =Output!K64 -> 0.3 | F10: =Output!J64 -> 0.7 | G10: =Output!K64 -> 0.3 | I10: =C10-F10 -> 0 | J10: =D10-G10 -> 0 | L10: Total | M10: =Output!E64 -> 0.85 | N10: =Output!F64 -> 0.15 | O10: =Output!G64 -> 0 | P10: =Output!H64 -> 1 | R10: =Output!E64 -> 0.85 | S10: =Output!F64 -> 0.15 | T10: =Output!G64 -> 0 | U10: =Output!H64 -> 1
B12: Development Output | L12: Development Output
B13: Peak Capital (net of preferred) | C13: =Output!J67 -> 20603.539 | D13: =Output!K67 -> 0 | F13: =Output!J67 -> 20603.539 | G13: =Output!K67 -> 0 | I13: =C13-F13 -> 0 | J13: =D13-G13 -> 0 | L13: Peak Capital (net of preferred) | M13: =Output!E67 -> 20603.539 | N13: =Output!F67 -> 0 | O13: =Output!G67 -> 0 | P13: =Output!H67 -> 20603.539 | R13: =Output!E67 -> 20603.539 | S13: =Output!F67 -> 0 | T13: =Output!G67 -> 0 | U13: =Output!H67 -> 20603.539
B15: Share of ORA Surplus | C15: =Output!J69 -> 12588.648 | D15: =Output!K69 -> 5395.1348 | F15: =Output!J69 -> 12588.648 | G15: =Output!K69 -> 5395.1348 | I15: =C15-F15 -> 0 | J15: =D15-G15 -> 0 | L15: Share of ORA Surplus | M15: =Output!E69 -> 15286.215 | N15: =Output!F69 -> 2697.5674 | O15: =Output!G69 -> 0 | P15: =Output!H69 -> 17983.783 | R15: =Output!E69 -> 15286.215 | S15: =Output!F69 -> 2697.5674 | T15: =Output!G69 -> 0 | U15: =Output!H69 -> 17983.783
B16: Share of Preferred Interest | C16: =Output!J70 -> 5250.6435 | D16: =Output!K70 -> 0 | F16: =Output!J70 -> 5250.6435 | G16: =Output!K70 -> 0 | I16: =C16-F16 -> 0 | J16: =D16-G16 -> 0 | L16: Share of Preferred Interest | M16: =Output!E70 -> 5250.6435 | N16: =Output!F70 -> 0 | O16: =Output!G70 -> 0 | P16: =Output!H70 -> 5250.6435 | R16: =Output!E70 -> 5250.6435 | S16: =Output!F70 -> 0 | T16: =Output!G70 -> 0 | U16: =Output!H70 -> 5250.6435
B17: Total | C17: =Output!J71 -> 17839.291 | D17: =Output!K71 -> 5395.1348 | F17: =Output!J71 -> 17839.291 | G17: =Output!K71 -> 5395.1348 | I17: =C17-F17 -> 0 | J17: =D17-G17 -> 0 | L17: Total | M17: =Output!E71 -> 20536.859 | N17: =Output!F71 -> 2697.5674 | O17: =Output!G71 -> 0 | P17: =Output!H71 -> 23234.426 | R17: =Output!E71 -> 20536.859 | S17: =Output!F71 -> 2697.5674 | T17: =Output!G71 -> 0 | U17: =Output!H71 -> 23234.426
B19: Margin (on share of costs) | C19: =Output!J73 -> 0.20597017 | D19: =Output!K73 -> n/a | F19: =Output!J73 -> 0.20597017 | G19: =Output!K73 -> n/a | I19: =C19-F19 -> 0 | J19: - | L19: Margin (on share of costs) | M19: =Output!E73 -> 0.23711593 | N19: =Output!F73 -> n/a | O19: =Output!G73 -> n/a | P19: =Output!H73 -> 0.2682617 | R19: =Output!E73 -> 0.23711593 | S19: =Output!F73 -> n/a | T19: =Output!G73 -> n/a | U19: =Output!H73 -> 0.2682617
B20: Margin (on share of capital) | C20: =Output!J74 -> 0.86583625 | D20: =Output!K74 -> n/a | F20: =Output!J74 -> 0.86583625 | G20: =Output!K74 -> n/a | I20: =C20-F20 -> 0 | J20: - | L20: Margin (on share of capital) | M20: =Output!E74 -> 0.99676362 | N20: =Output!F74 -> n/a | O20: =Output!G74 -> n/a | P20: =Output!H74 -> 1.127691 | R20: =Output!E74 -> 0.99676362 | S20: =Output!F74 -> n/a | T20: =Output!G74 -> n/a | U20: =Output!H74 -> 1.127691
B23: Long Term Investment | L23: Long Term Investment
B24: IRR (15 year - real basis) | C24: =Output!J78 -> 0.18860542 | D24: =Output!K78 -> 2.9802322e-09 | F24: =Output!J78 -> 0.18860542 | G24: =Output!K78 -> 2.9802322e-09 | I24: =C24-F24 -> 0 | J24: =D24-G24 -> 0 | L24: IRR (15 year - real basis) | M24: =Output!E78 -> 0.20309383 | N24: =Output!F78 -> n/a | O24: =Output!G78 -> n/a | P24: =Output!H78 -> 0.21641291 | R24: =Output!E78 -> 0.20309383 | S24: =Output!F78 -> n/a | T24: =Output!G78 -> n/a | U24: =Output!H78 -> 0.21641291
B26: Annual Cashflow (at maturity) | C26: =Output!J80 -> 2112.4824 | D26: =Output!K80 -> 905.34962 | F26: =Output!J80 -> 2112.4824 | G26: =Output!K80 -> 905.34962 | I26: =C26-F26 -> 0 | J26: =D26-G26 -> 0 | L26: Annual Cashflow (at maturity) | M26: =Output!E80 -> 2565.1573 | N26: =Output!F80 -> 452.67481 | O26: =Output!G80 -> 0 | P26: =Output!H80 -> 3017.8321 | R26: =Output!E80 -> 2565.1573 | S26: =Output!F80 -> 452.67481 | T26: =Output!G80 -> 0 | U26: =Output!H80 -> 3017.8321
B28: Investment Value (at maturity) | C28: =Output!J82 -> 12071.328 | D28: =Output!K82 -> 5173.4264 | F28: =Output!J82 -> 12071.328 | G28: =Output!K82 -> 5173.4264 | I28: =C28-F28 -> 0 | J28: =D28-G28 -> 0 | L28: Investment Value (at maturity) | M28: =Output!E82 -> 14658.041 | N28: =Output!F82 -> 2586.7132 | O28: =Output!G82 -> 0 | P28: =Output!H82 -> 17244.755 | R28: =Output!E82 -> 14658.041 | S28: =Output!F82 -> 2586.7132 | T28: =Output!G82 -> 0 | U28: =Output!H82 -> 17244.755
B30: Copy and Paste: | L30: Copy and Paste:
C32: Freehold | F32: Leasehold | I32: Variance | M32: 25% Vendor Share | R32: 50% Vendor Share
C34: A Class | D34: B Class | F34: A Class | G34: B Class | I34: A Class | J34: B Class | M34: Hāpai | N34: KPV | O34: Vendor | P34: Total | R34: Hāpai | S34: KPV | T34: Vendor | U34: Total
B35: Shareholdings | L35: Shareholdings
B36: A-Class | C36: 0.7 | D36: 0 | F36: 0.7 | G36: 0 | I36: =C36-F36 -> 0 | J36: =D36-G36 -> 0 | L36: A-Class | M36: 0.525 | N36: 0 | O36: 0.175 | P36: 0.7 | R36: 0.35 | S36: 0 | T36: 0.35 | U36: 0.7
B37: B-Class | C37: 0 | D37: 0.3 | F37: 0 | G37: 0.3 | I37: =C37-F37 -> 0 | J37: =D37-G37 -> 0 | L37: B-Class | M37: 0.15 | N37: 0.15 | O37: 0 | P37: 0.3 | R37: 0.15 | S37: 0.15 | T37: 0 | U37: 0.3
B38: Total | C38: 0.7 | D38: 0.3 | F38: 0.7 | G38: 0.3 | I38: =C38-F38 -> 0 | J38: =D38-G38 -> 0 | L38: Total | M38: 0.675 | N38: 0.15 | O38: 0.175 | P38: 1 | R38: 0.5 | S38: 0.15 | T38: 0.35 | U38: 1
B40: Development Output | L40: Development Output
B41: Peak Capital (net of preferred) | C41: 31858.35 | D41: 0 | F41: 17103.852 | G41: 0 | I41: =C41-F41 -> 14754.498 | J41: =D41-G41 -> 0 | L41: Peak Capital (net of preferred) | M41: 23893.763 | N41: 0 | O41: 7964.5875 | P41: 31858.35 | R41: 15929.175 | S41: 0 | T41: 15929.175 | U41: 31858.35
B43: Share of ORA Surplus | C43: 10535.836 | D43: 4515.3583 | F43: 23286.532 | G43: 9979.9423 | I43: =C43-F43 -> -12750.696 | J43: =D43-G43 -> -5464.584 | L43: Share of ORA Surplus | M43: 10159.556 | N43: 2257.6792 | O43: 2633.959 | P43: 15051.194 | R43: 7525.5972 | S43: 2257.6792 | T43: 5267.9181 | U43: 15051.194
B44: Share of Preferred Interest | C44: 11251.331 | D44: 0 | F44: 3794.605 | G44: 0 | I44: =C44-F44 -> 7456.7257 | J44: =D44-G44 -> 0 | L44: Share of Preferred Interest | M44: 8438.498 | N44: 0 | O44: 2812.8327 | P44: 11251.331 | R44: 5625.6654 | S44: 0 | T44: 5625.6654 | U44: 11251.331
B45: Total | C45: 21787.167 | D45: 4515.3583 | F45: 27081.137 | G45: 9979.9423 | I45: =C45-F45 -> -5293.9702 | J45: =D45-G45 -> -5464.584 | L45: Total | M45: 18598.054 | N45: 2257.6792 | O45: 5446.7917 | P45: 26302.525 | R45: 13151.263 | S45: 2257.6792 | T45: 10893.583 | U45: 26302.525
B47: Margin (on share of costs) | C47: 0.19722253 | D47: n/a | F47: 0.27159516 | G47: n/a | I47: =C47-F47 -> -0.074372624 | J47: - | L47: Margin (on share of costs) | M47: 0.22447192 | N47: n/a | O47: 0.19722253 | P47: 0.23809661 | R47: 0.23809661 | S47: n/a | T47: 0.19722253 | U47: 0.23809661
B48: Margin (on share of capital) | C48: 0.68387618 | D48: n/a | F48: 1.5833356 | G48: n/a | I48: =C48-F48 -> -0.89945939 | J48: - | L48: Margin (on share of capital) | M48: 0.7783644 | N48: n/a | O48: 0.68387618 | P48: 0.82560851 | R48: 0.82560851 | S48: n/a | T48: 0.68387618 | U48: 0.82560851
B51: Long Term Investment | L51: Long Term Investment
B52: IRR (15 year - real basis) | C52: 0.15064594 | D52: 2.9802322e-09 | F52: 0.28837599 | G52: 2.9802322e-09 | I52: =C52-F52 -> -0.13773005 | J52: =D52-G52 -> 0 | L52: IRR (15 year - real basis) | M52: 0.16317164 | N52: n/a | O52: 0.15064594 | P52: 0.1688893 | R52: 0.1688893 | S52: n/a | T52: 0.15064594 | U52: 0.1688893
B54: Annual Cashflow (at maturity) | C54: 2062.8409 | D54: 884.07469 | F54: 1123.9138 | G54: 481.67735 | I54: =C54-F54 -> 938.92711 | J54: =D54-G54 -> 402.39733 | L54: Annual Cashflow (at maturity) | M54: 1989.168 | N54: 442.03734 | O54: 515.71023 | P54: 2946.9156 | R54: 1473.4578 | S54: 442.03734 | T54: 1031.4205 | U54: 2946.9156
B56: Investment Value (at maturity) | C56: 11787.662 | D56: 5051.8554 | F56: 6422.3647 | G56: 2752.442 | I56: =C56-F56 -> 5365.2978 | J56: =D56-G56 -> 2299.4133 | L56: Investment Value (at maturity) | M56: 11366.675 | N56: 2525.9277 | O56: 2946.9156 | P56: 16839.518 | R56: 8419.7589 | S56: 2525.9277 | T56: 5893.8312 | U56: 16839.518

Sheet For Slides - Ground Lease
B2: Formula Driven: | L2: Formula Driven:
C4: Freehold | F4: Leasehold | I4: Variance | M4: 25% Vendor Share | R4: 50% Vendor Share
C6: A Class | D6: B Class | F6: A Class | G6: B Class | I6: A Class | J6: B Class | M6: Hāpai | N6: KPV | O6: Vendor | P6: Total | R6: Hāpai | S6: KPV | T6: Vendor | U6: Total
B7: Shareholdings | L7: Shareholdings
B8: A-Class | C8: =Output!J62 -> 0.7 | D8: =Output!K62 -> 0 | F8: =Output!J62 -> 0.7 | G8: =Output!K62 -> 0 | I8: =C8-F8 -> 0 | J8: =D8-G8 -> 0 | L8: A-Class | M8: =Output!E62 -> 0.7 | N8: =Output!F62 -> 0 | O8: =Output!G62 -> 0 | P8: =Output!H62 -> 0.7 | R8: =Output!E62 -> 0.7 | S8: =Output!F62 -> 0 | T8: =Output!G62 -> 0 | U8: =Output!H62 -> 0.7
B9: B-Class | C9: =Output!J63 -> 0 | D9: =Output!K63 -> 0.3 | F9: =Output!J63 -> 0 | G9: =Output!K63 -> 0.3 | I9: =C9-F9 -> 0 | J9: =D9-G9 -> 0 | L9: B-Class | M9: =Output!E63 -> 0.15 | N9: =Output!F63 -> 0.15 | O9: =Output!G63 -> 0 | P9: =Output!H63 -> 0.3 | R9: =Output!E63 -> 0.15 | S9: =Output!F63 -> 0.15 | T9: =Output!G63 -> 0 | U9: =Output!H63 -> 0.3
B10: Total | C10: =Output!J64 -> 0.7 | D10: =Output!K64 -> 0.3 | F10: =Output!J64 -> 0.7 | G10: =Output!K64 -> 0.3 | I10: =C10-F10 -> 0 | J10: =D10-G10 -> 0 | L10: Total | M10: =Output!E64 -> 0.85 | N10: =Output!F64 -> 0.15 | O10: =Output!G64 -> 0 | P10: =Output!H64 -> 1 | R10: =Output!E64 -> 0.85 | S10: =Output!F64 -> 0.15 | T10: =Output!G64 -> 0 | U10: =Output!H64 -> 1
B12: Development Output | L12: Development Output
B13: Peak Capital (net of preferred) | C13: =Output!J67 -> 20603.539 | D13: =Output!K67 -> 0 | F13: =Output!J67 -> 20603.539 | G13: =Output!K67 -> 0 | I13: =C13-F13 -> 0 | J13: =D13-G13 -> 0 | L13: Peak Capital (net of preferred) | M13: =Output!E67 -> 20603.539 | N13: =Output!F67 -> 0 | O13: =Output!G67 -> 0 | P13: =Output!H67 -> 20603.539 | R13: =Output!E67 -> 20603.539 | S13: =Output!F67 -> 0 | T13: =Output!G67 -> 0 | U13: =Output!H67 -> 20603.539
B15: Share of ORA Surplus | C15: =Output!J69 -> 12588.648 | D15: =Output!K69 -> 5395.1348 | F15: =Output!J69 -> 12588.648 | G15: =Output!K69 -> 5395.1348 | I15: =C15-F15 -> 0 | J15: =D15-G15 -> 0 | L15: Share of ORA Surplus | M15: =Output!E69 -> 15286.215 | N15: =Output!F69 -> 2697.5674 | O15: =Output!G69 -> 0 | P15: =Output!H69 -> 17983.783 | R15: =Output!E69 -> 15286.215 | S15: =Output!F69 -> 2697.5674 | T15: =Output!G69 -> 0 | U15: =Output!H69 -> 17983.783
B16: Share of Preferred Interest | C16: =Output!J70 -> 5250.6435 | D16: =Output!K70 -> 0 | F16: =Output!J70 -> 5250.6435 | G16: =Output!K70 -> 0 | I16: =C16-F16 -> 0 | J16: =D16-G16 -> 0 | L16: Share of Preferred Interest | M16: =Output!E70 -> 5250.6435 | N16: =Output!F70 -> 0 | O16: =Output!G70 -> 0 | P16: =Output!H70 -> 5250.6435 | R16: =Output!E70 -> 5250.6435 | S16: =Output!F70 -> 0 | T16: =Output!G70 -> 0 | U16: =Output!H70 -> 5250.6435
B17: Total | C17: =Output!J71 -> 17839.291 | D17: =Output!K71 -> 5395.1348 | F17: =Output!J71 -> 17839.291 | G17: =Output!K71 -> 5395.1348 | I17: =C17-F17 -> 0 | J17: =D17-G17 -> 0 | L17: Total | M17: =Output!E71 -> 20536.859 | N17: =Output!F71 -> 2697.5674 | O17: =Output!G71 -> 0 | P17: =Output!H71 -> 23234.426 | R17: =Output!E71 -> 20536.859 | S17: =Output!F71 -> 2697.5674 | T17: =Output!G71 -> 0 | U17: =Output!H71 -> 23234.426
B19: Margin (on share of costs) | C19: =Output!J73 -> 0.20597017 | D19: =Output!K73 -> n/a | F19: =Output!J73 -> 0.20597017 | G19: =Output!K73 -> n/a | I19: =C19-F19 -> 0 | J19: - | L19: Margin (on share of costs) | M19: =Output!E73 -> 0.23711593 | N19: =Output!F73 -> n/a | O19: =Output!G73 -> n/a | P19: =Output!H73 -> 0.2682617 | R19: =Output!E73 -> 0.23711593 | S19: =Output!F73 -> n/a | T19: =Output!G73 -> n/a | U19: =Output!H73 -> 0.2682617
B20: Margin (on share of capital) | C20: =Output!J74 -> 0.86583625 | D20: =Output!K74 -> n/a | F20: =Output!J74 -> 0.86583625 | G20: =Output!K74 -> n/a | I20: =C20-F20 -> 0 | J20: - | L20: Margin (on share of capital) | M20: =Output!E74 -> 0.99676362 | N20: =Output!F74 -> n/a | O20: =Output!G74 -> n/a | P20: =Output!H74 -> 1.127691 | R20: =Output!E74 -> 0.99676362 | S20: =Output!F74 -> n/a | T20: =Output!G74 -> n/a | U20: =Output!H74 -> 1.127691
B23: Long Term Investment | L23: Long Term Investment
B24: IRR (15 year - real basis) | C24: =Output!J78 -> 0.18860542 | D24: =Output!K78 -> 2.9802322e-09 | F24: =Output!J78 -> 0.18860542 | G24: =Output!K78 -> 2.9802322e-09 | I24: =C24-F24 -> 0 | J24: =D24-G24 -> 0 | L24: IRR (15 year - real basis) | M24: =Output!E78 -> 0.20309383 | N24: =Output!F78 -> n/a | O24: =Output!G78 -> n/a | P24: =Output!H78 -> 0.21641291 | R24: =Output!E78 -> 0.20309383 | S24: =Output!F78 -> n/a | T24: =Output!G78 -> n/a | U24: =Output!H78 -> 0.21641291
B26: Annual Cashflow (at maturity) | C26: =Output!J80 -> 2112.4824 | D26: =Output!K80 -> 905.34962 | F26: =Output!J80 -> 2112.4824 | G26: =Output!K80 -> 905.34962 | I26: =C26-F26 -> 0 | J26: =D26-G26 -> 0 | L26: Annual Cashflow (at maturity) | M26: =Output!E80 -> 2565.1573 | N26: =Output!F80 -> 452.67481 | O26: =Output!G80 -> 0 | P26: =Output!H80 -> 3017.8321 | R26: =Output!E80 -> 2565.1573 | S26: =Output!F80 -> 452.67481 | T26: =Output!G80 -> 0 | U26: =Output!H80 -> 3017.8321
B28: Investment Value (at maturity) | C28: =Output!J82 -> 12071.328 | D28: =Output!K82 -> 5173.4264 | F28: =Output!J82 -> 12071.328 | G28: =Output!K82 -> 5173.4264 | I28: =C28-F28 -> 0 | J28: =D28-G28 -> 0 | L28: Investment Value (at maturity) | M28: =Output!E82 -> 14658.041 | N28: =Output!F82 -> 2586.7132 | O28: =Output!G82 -> 0 | P28: =Output!H82 -> 17244.755 | R28: =Output!E82 -> 14658.041 | S28: =Output!F82 -> 2586.7132 | T28: =Output!G82 -> 0 | U28: =Output!H82 -> 17244.755
B30: Copy and Paste: | L30: Copy and Paste:
C32: Freehold | F32: Leasehold | I32: Variance | M32: 25% Vendor Share | R32: 50% Vendor Share
C34: A Class | D34: B Class | F34: A Class | G34: B Class | I34: A Class | J34: B Class | M34: Hāpai | N34: KPV | O34: Vendor | P34: Total | R34: Hāpai | S34: KPV | T34: Vendor | U34: Total
B35: Shareholdings | L35: Shareholdings
B36: A-Class | C36: 0.7 | D36: 0 | F36: 0.7 | G36: 0 | I36: =C36-F36 -> 0 | J36: =D36-G36 -> 0 | L36: A-Class | M36: 0.525 | N36: 0 | O36: 0.175 | P36: 0.7 | R36: 0.35 | S36: 0 | T36: 0.35 | U36: 0.7
B37: B-Class | C37: 0.15 | D37: 0.3 | F37: 0.15 | G37: 0.3 | I37: =C37-F37 -> 0 | J37: =D37-G37 -> 0 | L37: B-Class | M37: 0.15 | N37: 0.15 | O37: 0 | P37: 0.3 | R37: 0.15 | S37: 0.15 | T37: 0 | U37: 0.3
B38: Total | C38: 0.7 | D38: 0.3 | F38: 0.7 | G38: 0.3 | I38: =C38-F38 -> 0 | J38: =D38-G38 -> 0 | L38: Total | M38: 0.675 | N38: 0.15 | O38: 0.175 | P38: 1 | R38: 0.5 | S38: 0.15 | T38: 0.35 | U38: 1
B40: Development Output | L40: Development Output
B41: Peak Capital (net of preferred) | C41: 31858.35 | D41: 0 | F41: 17103.852 | G41: 0 | I41: =C41-F41 -> 14754.498 | J41: =D41-G41 -> 0 | L41: Peak Capital (net of preferred) | M41: 12827.889 | N41: 0 | O41: 4275.963 | P41: 17103.852 | R41: 8551.9259 | S41: 0 | T41: 8551.9259 | U41: 17103.852
B43: Share of ORA Surplus | C43: 10535.836 | D43: 4515.3583 | F43: 23286.532 | G43: 9979.9423 | I43: =C43-F43 -> -12750.696 | J43: =D43-G43 -> -5464.584 | L43: Share of ORA Surplus | M43: 22454.87 | N43: 4989.9711 | O43: 5821.633 | P43: 33266.474 | R43: 16633.237 | S43: 4989.9711 | T43: 11643.266 | U43: 33266.474
B44: Share of Preferred Interest | C44: 11251.331 | D44: 0 | F44: 3794.605 | G44: 0 | I44: =C44-F44 -> 7456.7257 | J44: =D44-G44 -> 0 | L44: Share of Preferred Interest | M44: 2845.9538 | N44: 0 | O44: 948.65126 | P44: 3794.605 | R44: 1897.3025 | S44: 0 | T44: 1897.3025 | U44: 3794.605
B45: Total | C45: 21787.167 | D45: 4515.3583 | F45: 27081.137 | G45: 9979.9423 | I45: =C45-F45 -> -5293.9702 | J45: =D45-G45 -> -5464.584 | L45: Total | M45: 25300.824 | N45: 4989.9711 | O45: 6770.2843 | P45: 37061.079 | R45: 18530.54 | S45: 4989.9711 | T45: 13540.569 | U45: 37061.079
B47: Margin (on share of costs) | C47: 0.19722253 | D47: n/a | F47: 0.27159516 | G47: n/a | I47: =C47-F47 -> -0.074372624 | J47: - | L47: Margin (on share of costs) | M47: 0.33832067 | N47: n/a | O47: 0.27159516 | P47: 0.37168342 | R47: 0.37168342 | S47: n/a | T47: 0.27159516 | U47: 0.37168342
B48: Margin (on share of capital) | C48: 0.68387618 | D48: n/a | F48: 1.5833356 | G48: n/a | I48: =C48-F48 -> -0.89945939 | J48: - | L48: Margin (on share of capital) | M48: 1.9723295 | N48: n/a | O48: 1.5833356 | P48: 2.1668265 | R48: 2.1668265 | S48: n/a | T48: 1.5833356 | U48: 2.1668265
B51: Long Term Investment | L51: Long Term Investment
B52: IRR (15 year - real basis) | C52: 0.15846584 | D52: 2.9802322e-09 | F52: 0.28743779 | G52: 2.9802322e-09 | I52: =C52-F52 -> -0.12897195 | J52: =D52-G52 -> 0 | L52: IRR (15 year - real basis) | M52: 0.32388808 | N52: n/a | O52: 0.28837599 | P52: 0.34009762 | R52: 0.34009762 | S52: n/a | T52: 0.28837599 | U52: 0.34009762
B54: Annual Cashflow (at maturity) | C54: 2062.8409 | D54: 884.07469 | F54: 1123.9138 | G54: 481.67735 | I54: =C54-F54 -> 938.92711 | J54: =D54-G54 -> 402.39733 | L54: Annual Cashflow (at maturity) | M54: 1083.774 | N54: 240.83868 | O54: 280.97846 | P54: 1605.5912 | R54: 802.79559 | S54: 240.83868 | T54: 561.95691 | U54: 1605.5912
B56: Investment Value (at maturity) | C56: 20628.409 | D56: 8840.7469 | F56: 4979.6241 | G56: 2134.1246 | I56: =C56-F56 -> 15648.785 | J56: =D56-G56 -> 6706.6222 | L56: Investment Value (at maturity) | M56: 6192.9945 | N56: 1376.221 | O56: 1605.5912 | P56: 9174.8067 | R56: 4587.4034 | S56: 1376.221 | T56: 3211.1823 | U56: 9174.8067
